Workbook
Name MileageRate: '860CBR'!$P$4
Name MileageRate: #REF!
Name MileageRate: #REF!
Name OKE: #REF!
Name Base: #REF!
Name MileageRate: '533CBR'!$P$4
Name Base: #REF!

Sheet 204
C2: =TODAY() -> 46283 | I2: COMPUTED TIME
C3: PK-AZI | I3: =F4-K3 -> 0.98958333 | K3: 0.25
C4: AWQ 204 | D4: CGK | E4: KUL | F4: 1.2395833 | G4: 0.32638889
C5: AWQ 205 | D5: =E4 -> KUL | E5: CGK | F5: 0.34375 | G5: 0.43055556 | H5: =C3 -> PK-AZI
C6: AWQ 274 | D6: CGK | E6: SIN | F6: 0.5625 | G6: 0.63541667 | I6: COMPUTED TIME
C7: AWQ 275 | D7: =E6 -> SIN | E7: CGK | F7: 0.66319444 | G7: 0.73611111 | I7: =F4-K7 -> 1.1145833 | K7: 0.125
C10: WAG | D10: CGO | E10: NAVTC | F10: CREAT | G10: TAXI | I10: ALTN | J10: TANKER | K10: SAVING
D11: 0 | E11: 0 | F11: 1000 | G11: =72+108 -> 180 | I11: WMSA | J11: 0 | K11: 0
D12: 0 | E12: 0 | F12: 1000 | G12: =96+108 -> 204 | I12: WILL | J12: 3000 | K12: 626.26
C17: PIC NAME | D17: CAPT. SUHANDI
C19: OFP1 | D19: 70794
C20: OFP2 | D20: 70795 | H20: iaa_cgk_ops@airasia.com
C21: OFP3
C22: OFP4
C25: MEL | D25: NIL

Sheet 204CBR
B2: CREW BRIEFING REPORT
B4: FLIGHT NO. | C4: 204/205 | F4: POD 1 | G4: WIII | I4: POA 1 | J4: WMKK | M4: ALTN | N4: ='204'!I11 -> WMSA | P4: OFP REF NO. | R4: ='204'!D19 -> 70794
B6: DATE | C6: =TODAY() -> 46283 | F6: POD 2 | G6: =J4 -> WMKK | I6: POA 2 | J6: WIII | M6: ALTN | N6: ='204'!I12 -> WILL | P6: OFP REF NO. | R6: ='204'!D20 -> 70795
B8: A/C REG | C8: ='204'!C3 -> PK-AZI | D8: ='204'!H5 -> PK-AZI | F8: POD 3 | G8: WIII | I8: POA 3 | J8: WSSS | M8: ALTN | N8: #REF! | P8: OFP REF NO. | R8: #REF!
F10: POD 4 | G10: =J8 -> WSSS | I10: POA 4 | J10: WIII | M10: ALTN | N10: #REF! | P10: OFP REF NO. | R10: #REF!
C12: Terminal Aerodrome Forecasts
C13: WIII | D13: TAF WIII 192300Z 2000/2106 20005KT 8000 FEW020 BECMG 2002/2004 36010KT BECMG 2013/2015 20005KT
C14: WMKK | D14: TAF WMKK 192300Z 2000/2106 VRB03KT 9999 FEW018 TEMPO 2015/2019 4000 TSRA FEW008 FEW017CB
C15: WMSA | D15: TAF WMSA 192300Z 2000/2100 VRB03KT 9999 FEW018 PROB30 TEMPO 2015/2019 4000 TSRA FEW017CB
C16: WMKJ | D16: TAF WMKJ 192300Z 2000/2100 20006KT 9000 FEW018 TEMPO 2000/2004 5000 TSRA FEW017CB SCT018
C17: WILL | D17: TAF WILL 192300Z 2000/2024 20003KT 9999 FEW020=
C18: WIPP | D18: TAF WIPP 192300Z 2000/2024 17008KT 9999 SCT015 TEMPO 2021/2024 5000 HZ
D20: STATION | E20: TIME | F20: Forecasts | K20: STATION | L20: STATION | M20: TIME | N20: Forecasts
D21: IDENTIFIER | K21: IDENTIFIER | L21: IDENTIFIER
C22: POD 1 | D22: WIII | E22: ='204'!F4 -> 1.2395833 | F22: 2000/2106 20005KT 8000 FEW020 | K22: POD 3 | L22: =G8 -> WIII | M22: #REF!
C23: POA 1 | D23: =J4 -> WMKK | E23: ='204'!G4 -> 0.32638889 | F23: 2000/2106 VRB03KT 9999 FEW018 | K23: POA 3 | L23: =J8 -> WSSS | M23: #REF!
C24: POD 2 | D24: =G6 -> WMKK | E24: ='204'!F5 -> 0.34375 | F24: 2000/2106 VRB03KT 9999 FEW018 | K24: POD 4 | L24: =G10 -> WSSS | M24: #REF!
C25: POA 2 | D25: =J6 -> WIII | E25: ='204'!G5 -> 0.43055556 | F25: 2000/2106 20005KT 8000 FEW020 | K25: POA 4 | L25: =J10 -> WIII | M25: #REF!
D28: STATION | E28: SIGNIFICANT NOTAM's
D29: IDENTIFIER
D31: WIII | E31: =#REF! -> #REF!
D32: WMKK | E32: =#REF! -> #REF!
D33: WMSA | E33: =#REF! -> #REF!
D34: WMKJ | E34: =#REF! -> #REF!
D35: WILL | E35: =#REF! -> #REF!
D36: WIPP | E36: =#REF! -> #REF!
C37: REMARK / ADDITIONAL NOTE : HEREBY CONFIRM THAT WE HAVE PERFORM FACE TO FACE BRIEFING
H39: DXR ON DUTY | P39: PIC
H40: NAME / SIGN | P40: NAME / SIGN
G44: DANDUNG TRIE H / 2677 | O44: ='204'!D17 -> CAPT. SUHANDI
H45: -------------------- | P45: -----------------------

Sheet 526
A2: =BB3 -> PKAZL | BB2: =TODAY() -> 46283 | BH2: COMPUTED TIME
A3: ` | N3: ` | AA3: ` | AN3: ` | BB3: PKAZL | BH3: =BE4-BJ3 -> 0.97222222 | BJ3: 0.25
B4: FUEL CHIT | J4: 1 | O4: FUEL CHIT | W4: 2 | AB4: FUEL CHIT | AJ4: 1 | AO4: FUEL CHIT | AW4: 2 | BB4: AWQ 526 | BC4: CGK | BD4: BKI | BE4: 1.2222222 | BF4: 0.32986111
BB5: AWQ 527 | BC5: =BD4 -> BKI | BD5: CGK | BE5: 0.35763889 | BF5: 0.46875
B6: FLIGHT NO | E6: =BB4 -> AWQ 526 | G6: BAY | O6: FLIGHT NO | R6: =BB5 -> AWQ 527 | T6: BAY | AB6: FLIGHT NO | AE6: =BB6 -> AWQ 814 | AG6: BAY | AO6: FLIGHT NO | AR6: =BB7 -> AWQ 815 | AT6: BAY | BB6: AWQ 814 | BC6: CGK | BD6: PNK | BE6: 0.34375 | BF6: 0.41319444
B7: ACFT REG | E7: =BB3 -> PKAZL | G7: ETD | H7: =BE4 -> 1.2222222 | O7: ACFT REG | R7: =E7 -> PKAZL | T7: ETD | U7: =BE5 -> 0.35763889 | AB7: ACFT REG | AE7: =R7 -> PKAZL | AG7: ETD | AH7: =BE6 -> 0.34375 | AO7: ACFT REG | AR7: =AE7 -> PKAZL | AT7: ETD | AU7: =BE7 -> 0.43055556 | BB7: AWQ 815 | BC7: =BD6 -> PNK | BD7: CGK | BE7: 0.43055556 | BF7: 0.49305556
B8: ORIGIN | E8: =BC4 -> CGK | G8: TRIP | H8: =BD11 -> 0 | O8: ORIGIN | R8: =BC5 -> BKI | T8: TRIP | U8: =BD12 -> 0 | AB8: ORIGIN | AE8: =BC6 -> CGK | AG8: TRIP | AH8: =BD13 -> 0 | AO8: ORIGIN | AR8: =BC7 -> PNK | AT8: TRIP | AU8: =BD14 -> 0
B9: DATE | E9: =BB2 -> 46283 | G9: NO.PAX | H9: =BB11 -> 0 | O9: DATE | R9: =E9 -> 46283 | T9: NO.PAX | U9: =BB12 -> 0 | AB9: DATE | AE9: =R9 -> 46283 | AG9: NO.PAX | AH9: =BB13 -> 0 | AO9: DATE | AR9: =AE9 -> 46283 | AT9: NO.PAX | AU9: =BB14 -> 0
BB10: WAG | BC10: CGO | BD10: nvtec | BE10: CREAT | BF10: TAXI | BG10: EZFW | BH10: ATLN | BI10: TANKER | BJ10: SAVING
B11: REGULATED LDG WT | G11: 66000 | O11: REGULATED LDG WT | T11: 66000 | AB11: REGULATED LDG WT | AG11: 66000 | AO11: REGULATED LDG WT | AT11: 66000 | BC11: 0 | BD11: 0 | BE11: 1000 | BF11: =72+48 -> 120 | BH11: WBGG | BI11: 0 | BJ11: 0
B12: ADD BURN OFF | G12: =H8 -> 0 | O12: ADD BURN OFF | T12: =U8 -> 0 | AB12: ADD BURN OFF | AG12: =AH8 -> 0 | AO12: ADD BURN OFF | AT12: =BD14 -> 0 | BC12: 0 | BD12: 0 | BE12: 1000 | BF12: =120+120 -> 240 | BH12: WIPP | BI12: 3000 | BJ12: 329.75
B13: REGULATED TKOF WT | F13: A | G13: =G11+G12 -> 66000 | O13: REGULATED TKOF WT | S13: A | T13: =T11+T12 -> 66000 | AB13: REGULATED TKOF WT | AF13: A | AG13: =AG11+AG12 -> 66000 | AO13: REGULATED TKOF WT | AS13: A | AT13: =AT11+AT12 -> 66000
B15: FORECAST WIND | I15: FLAP | O15: FORECAST WIND | V15: FLAP | AB15: FORECAST WIND | AI15: FLAP | AO15: FORECAST WIND | AV15: FLAP
B16: TEMP | E16: RWY | I16: QNH | O16: TEMP | R16: RWY | V16: QNH | AB16: TEMP | AE16: RWY | AI16: QNH | AO16: TEMP | AR16: RWY | AV16: QNH
B17: REGULATED TKOF WT | F17: B | G17: 73500 | O17: REGULATED TKOF WT | S17: B | T17: =G17 -> 73500 | AB17: REGULATED TKOF WT | AF17: B | AG17: =T17 -> 73500 | AO17: REGULATED TKOF WT | AS17: B | AT17: =AG17 -> 73500 | BB17: PIC NAME : | BC17: CAPT. HUSIN ABDILLAH ALAYDRUS
BH18: iaa_cgk_ops@airasia.com
B19: LOWER RTOW A OR B | G19: =G13 -> 66000 | O19: LOWER RTOW A OR B | T19: =T13 -> 66000 | AB19: LOWER RTOW A OR B | AG19: =AG13 -> 66000 | AO19: LOWER RTOW A OR B | AT19: =AT13 -> 66000 | BB19: OFP1 | BC19: 71076
B20: ESTIMATED ZFW | G20: =BG11 -> 0 | O20: ESTIMATED ZFW | T20: =BG12 -> 0 | AB20: ESTIMATED ZFW | AG20: =BG13 -> 0 | AO20: ESTIMATED ZFW | AT20: =BG14 -> 0 | BB20: OFP2 | BC20: 71077
B21: MAX FUEL AVAILABLE | G21: =G19-G20 -> 66000 | O21: MAX FUEL AVAILABLE | T21: =T19-T20 -> 66000 | AB21: MAX FUEL AVAILABLE | AG21: =AG19-AG20 -> 66000 | AO21: MAX FUEL AVAILABLE | AT21: =AT19-AT20 -> 66000 | BB21: OFP3
B22: MIN SECTOR FUEL | G22: =BE11 -> 1000 | O22: MIN SECTOR FUEL | T22: =BE12 -> 1000 | AB22: MIN SECTOR FUEL | AG22: =BE13 -> 0 | AO22: MIN SECTOR FUEL | AT22: =BE14 -> 0 | BB22: OFP4
B23: EXCESS FUEL AVAILABLE | G23: =G21-G22 -> 65000 | O23: EXCESS FUEL AVAILABLE | T23: =T21-T22 -> 65000 | AB23: EXCESS FUEL AVAILABLE | AG23: =AG21-AG22 -> 66000 | AO23: EXCESS FUEL AVAILABLE | AT23: =AT21-AT22 -> 66000
BB24: MEL
B25: LOADSHEET | O25: LOADSHEET | AB25: LOADSHEET | AO25: LOADSHEET
B26: PLUS TAXI FUEL | G26: =BF11 -> 120 | O26: PLUS TAXI FUEL | T26: =BF12 -> 240 | AB26: PLUS TAXI FUEL | AG26: =BF13 -> 0 | AO26: PLUS TAXI FUEL | AT26: =BF14 -> 0
B27: FUEL IN TANKS (KG) | O27: FUEL IN TANKS (KG) | AB27: FUEL IN TANKS (KG) | AO27: FUEL IN TANKS (KG)
B30: SIGNATURE : | E30: =BC17 -> CAPT. HUSIN ABDILLAH ALAYDRUS | O30: SIGNATURE : | R30: =E30 -> CAPT. HUSIN ABDILLAH ALAYDRUS | AB30: SIGNATURE : | AE30: =R30 -> CAPT. HUSIN ABDILLAH ALAYDRUS | AO30: SIGNATURE : | AR30: =AE30 -> CAPT. HUSIN ABDILLAH ALAYDRUS
D31: ( CAPTAIN ) | Q31: ( CAPTAIN ) | AD31: ( CAPTAIN ) | AQ31: ( CAPTAIN )
B34: EST CGO : | D34: =BC11 -> 0 | G34: KGS | O34: EST CGO : | Q34: =BC12 -> 0 | T34: KGS | AB34: EST CGO : | AD34: =BC13 -> 0 | AG34: KGS | AO34: EST CGO : | AQ34: =BC14 -> 0 | AT34: KGS

Sheet 526CBR
B2: CREW BRIEFING REPORT
B4: FLIGHT NO. | C4: 526/527 | F4: POD 1 | G4: WIII | I4: POA 1 | J4: WBKK | M4: ALTN | N4: ='526'!BH11 -> WBGG | P4: OFP REF NO. | R4: ='526'!BC19 -> 71076
B6: DATE | C6: ='526'!BB2 -> 46283 | F6: POD 2 | G6: =J4 -> WBKK | I6: POA 2 | J6: WIII | M6: ALTN | N6: ='526'!BH12 -> WIPP | P6: OFP REF NO. | R6: ='526'!BC20 -> 71077
B8: A/C REG | C8: ='526'!BB3 -> PKAZL | F8: POD 3 | G8: =J6 -> WIII | I8: POA 3 | J8: WIOO | M8: ALTN | N8: ='526'!BH13 -> 0 | P8: OFP REF NO. | R8: ='526'!BC21 -> 0
F10: POD 4 | G10: =J8 -> WIOO | I10: POA 4 | J10: WIII | M10: ALTN | N10: ='526'!BH14 -> 0 | P10: OFP REF NO. | R10: ='526'!BC22 -> 0
C12: Terminal Aerodrome Forecasts
C13: WIII | D13: TAF WIII 202300Z 2100/2206 VRB02KT 8000 FEW020 BECMG 2102/2104 36010KT BECMG 2114/2116 22005KT 5000 HZ
C14: WBKK | D14: TAF WBKK 202300Z 2100/2200 25006KT 9999 FEW014 TEMPO 2105/2110 5000 TSRA FEW013 FEW016CB SCT035 BECMG 2110/2112 11006KT
C15: WBGG | D15: TAF WBGG 202300Z 2100/2200 VRB03KT 9999 FEW020
C16: WIPP | D16: TAF WIPP 202300Z 2100/2124 09008KT 9999 SCT015 TEMPO 2121/2124 5000 HZ
C17: WILL | D17: TAF WILL 202300Z 2100/2124 12007KT 9999 FEW015 BECMG 2114/2116 00000KT=
D19: STATION | E19: TIME | F19: Forecasts | K19: STATION | L19: STATION | M19: TIME | N19: Forecasts
D20: IDENTIFIER | K20: IDENTIFIER | L20: IDENTIFIER
C21: POD 1 | D21: =G4 -> WIII | E21: ='526'!BE4 -> 1.2222222 | F21: 2100/2206 VRB02KT 8000 FEW020 | K21: POD 3 | L21: =G8 -> WIII | M21: ='526'!BE6 -> 0.34375
C22: POA 1 | D22: =J4 -> WBKK | E22: ='526'!BF4 -> 0.32986111 | F22: TEMPO 2105/2110 5000 TSRA FEW013 FEW016CB SCT035 | K22: POA 3 | L22: =J8 -> WIOO | M22: ='526'!BF6 -> 0.41319444
C23: POD 2 | D23: =G6 -> WBKK | E23: ='526'!BE5 -> 0.35763889 | F23: TEMPO 2105/2110 5000 TSRA FEW013 FEW016CB SCT035 | K23: POD 4 | L23: =G10 -> WIOO | M23: ='526'!BE7 -> 0.43055556
C24: POA 2 | D24: =J6 -> WIII | E24: ='526'!BF5 -> 0.46875 | F24: 2100/2206 VRB02KT 8000 FEW020 | K24: POA 4 | L24: =J10 -> WIII | M24: ='526'!BF7 -> 0.49305556
D27: STATION | E27: SIGNIFICANT NOTAM's
D28: IDENTIFIER
D30: WIII | E30: =#REF! -> #REF!
D31: WBKK | E31: =#REF! -> #REF!
D32: WBGG | E32: =#REF! -> #REF!
D33: WBSB | E33: =#REF! -> #REF!
D34: WIPP | E34: =#REF! -> #REF!
D35: =C17 -> WILL | E35: =#REF! -> #REF!
H37: DXR ON DUTY | P37: PIC
H38: NAME / SIGN | P38: NAME / SIGN
G41: DANDUNG TRIE H / 2677 | O41: ='526'!BC17 -> CAPT. HUSIN ABDILLAH ALAYDRUS
H42: -------------------- | P42: -----------------------

Sheet CBR
Q2: Rec. No. :
E3: Crew Briefing Report Form | Q3: Date :
Q4: Page : 1 of 1
B7: FLIGHT NO. | G7: POD 1 | J7: POA 1 | N7: ALTN | Q7: OFP REF NO.
B9: DATE | G9: POD 2 | J9: POA 2 | N9: ALTN | Q9: OFP REF NO.
B11: A/C REG | G11: POD 3 | J11: POA 3 | N11: ALTN | Q11: OFP REF NO.
G13: POD 4 | J13: POA 4 | N13: ALTN | Q13: OFP REF NO.
G15: POD 5 | J15: POA 5 | N15: ALTN | Q15: OFP REF NO.
G17: POD 6 | J17: POA 6 | N17: ALTN | Q17: OFP REF NO.
C19: Terminal Aerodrome Forecasts
E28: STATION | F28: TIME | G28: Forecasts | M28: STATION | O28: TIME | P28: Forecasts
E29: IDENTIFIER | M29: IDENTIFIER
C30: POD 1 | K30: POD 4
C31: POA 1 | K31: POA 4
C32: POD 2 | K32: POD 5
C33: POA 2 | K33: POA 5
C34: POD 3 | K34: POD 6
C35: POA 3 | K35: POA 6
C37: STATION | E37: SIGNIFICANT NOTAM's
C38: IDENTIFIER
E47: DXR ON DUTY | O47: PIC
E48: NAME / SIGN | O48: NAME / SIGN
E51: ----------------------------------- | O51: -----------------------------------
C53: 45992 | R53: IAA/OCC/F/001 Rev.03

Sheet 860
A2: =BB3 -> PKAZJ | BB2: =TODAY() -> 46283 | BH2: COMPUTED TIME
A3: ` | N3: ` | AA3: ` | AN3: ` | BB3: PKAZJ | BH3: =BE4-BJ3 -> 0.98611111 | BJ3: 0.25
B4: FUEL CHIT | J4: 1 | O4: FUEL CHIT | W4: 2 | AB4: FUEL CHIT | AJ4: 3 | AO4: FUEL CHIT | AW4: 4 | BB4: AWQ 860 | BC4: CGK | BD4: LBJ | BE4: 1.2361111 | BF4: 0.33680556
BB5: AWQ 861 | BC5: =BD4 -> LBJ | BD5: CGK | BE5: 0.35763889 | BF5: 0.45486111
B6: FLIGHT NO | E6: =BB4 -> AWQ 860 | G6: BAY | O6: FLIGHT NO | R6: =BB5 -> AWQ 861 | T6: BAY | AB6: FLIGHT NO | AE6: =BB6 -> AWQ 7532 | AG6: BAY | AO6: FLIGHT NO | AR6: =BB7 -> AWQ 7531 | AT6: BAY | BB6: AWQ 7532 | BC6: CGK | BD6: DPS | BE6: 0.13888889 | BF6: 0.21527778
B7: ACFT REG | E7: =BB3 -> PKAZJ | G7: ETD | H7: =BE4 -> 1.2361111 | O7: ACFT REG | R7: =E7 -> PKAZJ | T7: ETD | U7: =BE5 -> 0.35763889 | AB7: ACFT REG | AE7: =R7 -> PKAZJ | AG7: ETD | AH7: =BE6 -> 0.13888889 | AO7: ACFT REG | AR7: =AE7 -> PKAZJ | AT7: ETD | AU7: =BE7 -> 0.23263889 | BB7: AWQ 7531 | BC7: =BD6 -> DPS | BD7: CGK | BE7: 0.23263889 | BF7: 0.30902778
B8: ORIGIN | E8: =BC4 -> CGK | G8: TRIP | H8: =BD11 -> 1062 | O8: ORIGIN | R8: =BC5 -> LBJ | T8: TRIP | U8: =BD12 -> 182 | AB8: ORIGIN | AE8: =BC6 -> CGK | AG8: TRIP | AH8: =BD13 -> 0 | AO8: ORIGIN | AR8: =BC7 -> DPS | AT8: TRIP | AU8: =BD14 -> 0
B9: DATE | E9: =BB2 -> 46283 | G9: NO.PAX | H9: =BB11 -> 0 | O9: DATE | R9: =E9 -> 46283 | T9: NO.PAX | U9: =BB12 -> 0 | AB9: DATE | AE9: =R9 -> 46283 | AG9: NO.PAX | AH9: =BB13 -> 0 | AO9: DATE | AR9: =AE9 -> 46283 | AT9: NO.PAX | AU9: =BB14 -> 0
BB10: PAX | BC10: CGO | BD10: NAVT | BE10: CREAT | BF10: TAXI | BG10: EZFW | BH10: ALTN | BI10: TANKER | BJ10: SAVING
B11: REGULATED LDG WT | G11: 66000 | O11: REGULATED LDG WT | T11: 66000 | AB11: REGULATED LDG WT | AG11: 66000 | AO11: REGULATED LDG WT | AT11: 66000 | BC11: 1062 | BD11: 1062 | BE11: 1500 | BF11: =72+36 -> 108 | BH11: WADL | BI11: 2000 | BJ11: 95.2
B12: ADD BURN OFF | G12: =H8 -> 1062 | O12: ADD BURN OFF | T12: =U8 -> 182 | AB12: ADD BURN OFF | AG12: =AH8 -> 0 | AO12: ADD BURN OFF | AT12: =AU8 -> 0 | BC12: 182 | BD12: 182 | BE12: 1000 | BF12: =72+108 -> 180 | BH12: WIPP | BI12: 0 | BJ12: 0
B13: REGULATED TKOF WT | F13: A | G13: =G11+G12 -> 67062 | O13: REGULATED TKOF WT | S13: A | T13: =T11+T12 -> 66182 | AB13: REGULATED TKOF WT | AF13: A | AG13: =AG11+AG12 -> 66000 | AO13: REGULATED TKOF WT | AS13: A | AT13: =AT11+AT12 -> 66000
B15: FORECAST WIND | I15: FLAP | O15: FORECAST WIND | V15: FLAP | AB15: FORECAST WIND | AI15: FLAP | AO15: FORECAST WIND | AV15: FLAP
B16: TEMP | E16: RWY | I16: QNH | O16: TEMP | R16: RWY | V16: QNH | AB16: TEMP | AE16: RWY | AI16: QNH | AO16: TEMP | AR16: RWY | AV16: QNH
B17: REGULATED TKOF WT | F17: B | G17: 73500 | O17: REGULATED TKOF WT | S17: B | T17: =G17 -> 73500 | AB17: REGULATED TKOF WT | AF17: B | AG17: =T17 -> 73500 | AO17: REGULATED TKOF WT | AS17: B | AT17: =AG17 -> 73500 | BB17: PIC NAME | BC17: CAPT. AFNER SYAFRIL
B19: LOWER RTOW A OR B | G19: =G17 -> 73500 | O19: LOWER RTOW A OR B | T19: =T17 -> 73500 | AB19: LOWER RTOW A OR B | AG19: =AG13 -> 66000 | AO19: LOWER RTOW A OR B | AT19: =AT13 -> 66000 | BB19: OFP1 | BC19: 71080
B20: ESTIMATED ZFW | G20: =BG11 -> 0 | O20: ESTIMATED ZFW | T20: =BG12 -> 0 | AB20: ESTIMATED ZFW | AG20: =BG13 -> 0 | AO20: ESTIMATED ZFW | AT20: =BG14 -> 0 | BB20: OFP2 | BC20: 71082
B21: MAX FUEL AVAILABLE | G21: =G19-G20 -> 73500 | O21: MAX FUEL AVAILABLE | T21: =T19-T20 -> 73500 | AB21: MAX FUEL AVAILABLE | AG21: =AG19-AG20 -> 66000 | AO21: MAX FUEL AVAILABLE | AT21: =AT19-AT20 -> 66000 | BB21: OFP3
B22: MIN SECTOR FUEL | G22: =BE11 -> 1500 | O22: MIN SECTOR FUEL | T22: =BE12 -> 1000 | AB22: MIN SECTOR FUEL | AG22: =BE13 -> 0 | AO22: MIN SECTOR FUEL | AT22: =BE14 -> 0 | BB22: OFP4
B23: EXCESS FUEL AVAILABLE | G23: =G21-G22 -> 72000 | O23: EXCESS FUEL AVAILABLE | T23: =T21-T22 -> 72500 | AB23: EXCESS FUEL AVAILABLE | AG23: =AG21-AG22 -> 66000 | AO23: EXCESS FUEL AVAILABLE | AT23: =AT21-AT22 -> 66000
BB24: MEL | BC24: NIL
B25: LOADSHEET | O25: LOADSHEET | AB25: LOADSHEET | AO25: LOADSHEET
B26: PLUS TAXI FUEL | G26: =BF11 -> 108 | O26: PLUS TAXI FUEL | T26: =BF12 -> 180 | AB26: PLUS TAXI FUEL | AG26: =BF13 -> 0 | AO26: PLUS TAXI FUEL | AT26: =BF14 -> 0
B27: FUEL IN TANKS (KG) | O27: FUEL IN TANKS (KG) | AB27: FUEL IN TANKS (KG) | AO27: FUEL IN TANKS (KG)
B30: SIGNATURE : | E30: =BC17 -> CAPT. AFNER SYAFRIL | O30: SIGNATURE : | R30: =E30 -> CAPT. AFNER SYAFRIL | AB30: SIGNATURE : | AE30: =R30 -> CAPT. AFNER SYAFRIL | AO30: SIGNATURE : | AR30: =AE30 -> CAPT. AFNER SYAFRIL
D31: ( CAPTAIN ) | Q31: ( CAPTAIN ) | AD31: ( CAPTAIN ) | AQ31: ( CAPTAIN )
B34: EST CGO : | D34: =BC11 -> 1062 | G34: KGS | O34: EST CGO : | Q34: =BC12 -> 182 | T34: KGS | AB34: EST CGO : | AD34: =BC13 -> 0 | AG34: KGS | AO34: EST CGO : | AQ34: =BC14 -> 0 | AT34: KGS

Sheet 860CBR
B2: CREW BRIEFING REPORT
B4: FLIGHT NO. | C4: 860/861 | F4: POD 1 | G4: WIII | I4: POA 1 | J4: WATO | M4: ALTN | N4: ='860'!BH11 -> WADL | P4: OFP REF NO. | R4: ='860'!BC19 -> 71080
B6: DATE | C6: ='860'!BB2 -> 46283 | F6: POD 2 | G6: =J4 -> WATO | I6: POA 2 | J6: WIII | M6: ALTN | N6: ='860'!BH12 -> WIPP | P6: OFP REF NO. | R6: ='860'!BC20 -> 71082
B8: A/C REG | C8: ='860'!BB3 -> PKAZJ | F8: POD 3 | G8: WIII | I8: POA 3 | J8: WADD | M8: ALTN | N8: ='860'!BH13 -> 0 | P8: OFP REF NO. | R8: ='860'!BC21 -> 0
F10: POD 4 | G10: =J8 -> WADD | I10: POA 4 | J10: WIII | M10: ALTN | N10: ='860'!BH14 -> 0 | P10: OFP REF NO. | R10: ='860'!BC22 -> 0
C12: Terminal Aerodrome Forecasts
C13: WIII | D13: ='526CBR'!D13 -> TAF WIII 202300Z 2100/2206 VRB02KT 8000 FEW020 BECMG 2102/2104 36010KT BECMG 2114/2116 22005KT 5000 HZ
C14: WATO | D14: TAF WATO 202300Z 2100/2112 03014KT 9999 FEW020 BECMG 2109/2111 21004KT=
C15: WADL | D15: =[1]INPUT!D15 -> #REF!
C16: WILL | D16: ='526CBR'!D17 -> TAF WILL 202300Z 2100/2124 12007KT 9999 FEW015 BECMG 2114/2116 00000KT=
C17: WIPP | D17: ='526CBR'!D16 -> TAF WIPP 202300Z 2100/2124 09008KT 9999 SCT015 TEMPO 2121/2124 5000 HZ
D19: STATION | E19: TIME | F19: Forecasts | K19: STATION | L19: STATION | M19: TIME | N19: Forecasts
D20: IDENTIFIER | K20: IDENTIFIER | L20: IDENTIFIER
C21: POD 1 | D21: =G4 -> WIII | E21: ='860'!BE4 -> 1.2361111 | F21: 2100/2206 VRB02KT 8000 FEW020 | K21: POD 3 | L21: =G8 -> WIII | M21: ='860'!BE6 -> 0.13888889
C22: POA 1 | D22: =J4 -> WATO | E22: ='860'!BF4 -> 0.33680556 | F22: 2100/2112 03014KT 9999 FEW020 | K22: POA 3 | L22: =J8 -> WADD | M22: ='860'!BF6 -> 0.21527778
C23: POD 2 | D23: =G6 -> WATO | E23: ='860'!BE5 -> 0.35763889 | F23: 2100/2112 03014KT 9999 FEW020 | K23: POD 4 | L23: =G10 -> WADD | M23: ='860'!BE7 -> 0.23263889
C24: POA 2 | D24: =J6 -> WIII | E24: ='860'!BF5 -> 0.45486111 | F24: 2100/2206 VRB02KT 8000 FEW020 | K24: POA 4 | L24: =J10 -> WIII | M24: ='860'!BF7 -> 0.30902778
D27: STATION | E27: SIGNIFICANT NOTAM's
D28: IDENTIFIER
D30: WIII | E30: =#REF! -> #REF!
D31: WATO | E31: No active NOTAMs for this location.
D32: WADL | E32: =#REF! -> #REF!
D33: WILL | E33: =#REF! -> #REF!
D34: WIPP | E34: =#REF! -> #REF!
C35: REMARK / ADDITIONAL NOTE : HEREBY CONFIRM THAT WE HAVE PERFORM FACE TO FACE BRIEFING
H37: DXR ON DUTY | P37: PIC
H38: NAME / SIGN | P38: NAME / SIGN
G42: DANDUNG TRIE H / 2677 | O42: ='860'!BC17 -> CAPT. AFNER SYAFRIL
H43: -------------------- | P43: -----------------------

Sheet 533
A2: =BB3 -> PK-AZD | BB2: =TODAY() -> 46283 | BH2: COMPUTED TIME
A3: ` | N3: ` | AA3: ` | AN3: ` | BB3: PK-AZD | BH3: =BE4-BJ3 -> 0.15972222 | BJ3: 0.25
B4: FUEL CHIT | J4: 1 | O4: FUEL CHIT | W4: 2 | AB4: FUEL CHIT | AJ4: 3 | AO4: FUEL CHIT | AW4: 4 | BB4: AWQ 533 | BC4: PER | BD4: CGK | BE4: 0.40972222 | BF4: 0.60763889
BB5: AWQ 7533 | BC5: =BD4 -> CGK | BD5: CGK | BE5: 0.65972222 | BF5: 0.73611111
B6: FLIGHT NO | E6: =BB4 -> AWQ 533 | G6: BAY | O6: FLIGHT NO | R6: =BB5 -> AWQ 7533 | T6: BAY | AB6: FLIGHT NO | AE6: =BB6 -> AWQ 802 | AG6: BAY | AO6: FLIGHT NO | AR6: =BB7 -> AWQ 803 | AT6: BAY | BB6: AWQ 802 | BC6: CGK | BD6: PKU | BE6: 0.4375 | BF6: 0.51041667
B7: ACFT REG | E7: =BB3 -> PK-AZD | G7: ETD | H7: =BE4 -> 0.40972222 | O7: ACFT REG | R7: =E7 -> PK-AZD | T7: ETD | U7: =BE5 -> 0.65972222 | AB7: ACFT REG | AE7: =R7 -> PK-AZD | AG7: ETD | AH7: =BE6 -> 0.4375 | AO7: ACFT REG | AR7: =AE7 -> PK-AZD | AT7: ETD | AU7: =BE7 -> 0.52777778 | BB7: AWQ 803 | BC7: PKU | BD7: CGK | BE7: 0.52777778 | BF7: 0.60069444
B8: ORIGIN | E8: =BC4 -> PER | G8: TRIP | H8: =BD11 -> 0 | O8: ORIGIN | R8: =BC5 -> CGK | T8: TRIP | U8: =BD12 -> 0 | AB8: ORIGIN | AE8: =BC6 -> CGK | AG8: TRIP | AH8: =BD13 -> 0 | AO8: ORIGIN | AR8: =BC7 -> PKU | AT8: TRIP | AU8: =BD14 -> 0
B9: DATE | E9: =BB2-1 -> 46282 | G9: NO.PAX | H9: =BB11 -> 0 | O9: DATE | R9: =E9+1 -> 46283 | T9: NO.PAX | U9: =BB12 -> 0 | AB9: DATE | AE9: =R9 -> 46283 | AG9: NO.PAX | AH9: =BB13 -> 0 | AO9: DATE | AR9: =AE9 -> 46283 | AT9: NO.PAX | AU9: =BB14 -> 0
BB10: WAG | BC10: CGO | BD10: NAVT | BE10: CREAT | BF10: TAXI | BG10: EZFW | BH10: ALTN | BI10: TANKER | BJ10: SAVING
B11: REGULATED LDG WT | G11: 66000 | O11: REGULATED LDG WT | T11: 66000 | AB11: REGULATED LDG WT | AG11: 66000 | AO11: REGULATED LDG WT | AT11: 66000 | BC11: 500 | BD11: 0 | BE11: 0 | BF11: =96+96 -> 192 | BH11: WIPP | BI11: 1000 | BJ11: 27.65
B12: ADD BURN OFF | G12: =H8 -> 0 | O12: ADD BURN OFF | T12: =U8 -> 0 | AB12: ADD BURN OFF | AG12: =AH8 -> 0 | AO12: ADD BURN OFF | AT12: =AU8 -> 0
B13: REGULATED TKOF WT | F13: A | G13: =G11+G12 -> 66000 | O13: REGULATED TKOF WT | S13: A | T13: =T11+T12 -> 66000 | AB13: REGULATED TKOF WT | AF13: A | AG13: =AG11+AG12 -> 66000 | AO13: REGULATED TKOF WT | AS13: A | AT13: =AT11+AT12 -> 66000
B15: FORECAST WIND | I15: FLAP | O15: FORECAST WIND | V15: FLAP | AB15: FORECAST WIND | AI15: FLAP | AO15: FORECAST WIND | AV15: FLAP
B16: TEMP | E16: RWY | I16: QNH | O16: TEMP | R16: RWY | V16: QNH | AB16: TEMP | AE16: RWY | AI16: QNH | AO16: TEMP | AR16: RWY | AV16: QNH
B17: REGULATED TKOF WT | F17: B | G17: 73500 | O17: REGULATED TKOF WT | S17: B | T17: =G17 -> 73500 | AB17: REGULATED TKOF WT | AF17: B | AG17: =T17 -> 73500 | AO17: REGULATED TKOF WT | AS17: B | AT17: =AG17 -> 73500 | BB17: PIC NAME | BC17: CAPT. DAVID WIBAWA SAPULETE
B19: LOWER RTOW A OR B | G19: =G13 -> 66000 | O19: LOWER RTOW A OR B | T19: =T13 -> 66000 | AB19: LOWER RTOW A OR B | AG19: =AG13 -> 66000 | AO19: LOWER RTOW A OR B | AT19: =AT13 -> 66000 | BB19: OFP1 | BC19: 70851 | BG19: iaa_cgk_ops@airasia.com
B20: ESTIMATED ZFW | G20: =BG11 -> 0 | O20: ESTIMATED ZFW | T20: =BG12 -> 0 | AB20: ESTIMATED ZFW | AG20: =BG13 -> 0 | AO20: ESTIMATED ZFW | AT20: =BG14 -> 0 | BB20: OFP2
B21: MAX FUEL AVAILABLE | G21: =G19-G20 -> 66000 | O21: MAX FUEL AVAILABLE | T21: =T19-T20 -> 66000 | AB21: MAX FUEL AVAILABLE | AG21: =AG19-AG20 -> 66000 | AO21: MAX FUEL AVAILABLE | AT21: =AT19-AT20 -> 66000 | BB21: OFP3
B22: MIN SECTOR FUEL | G22: =BE11 -> 0 | O22: MIN SECTOR FUEL | T22: =BE12 -> 0 | AB22: MIN SECTOR FUEL | AG22: =BE13 -> 0 | AO22: MIN SECTOR FUEL | AT22: =BE14 -> 0 | BB22: OFP4
B23: EXCESS FUEL AVAILABLE | G23: =G21-G22 -> 66000 | O23: EXCESS FUEL AVAILABLE | T23: =T21-T22 -> 66000 | AB23: EXCESS FUEL AVAILABLE | AG23: =AG21-AG22 -> 66000 | AO23: EXCESS FUEL AVAILABLE | AT23: =AT21-AT22 -> 66000
BB24: MEL
B25: LOADSHEET | O25: LOADSHEET | AB25: LOADSHEET | AO25: LOADSHEET
B26: PLUS TAXI FUEL | G26: =BF11 -> 192 | O26: PLUS TAXI FUEL | T26: =BF12 -> 0 | AB26: PLUS TAXI FUEL | AG26: =BF13 -> 0 | AO26: PLUS TAXI FUEL | AT26: =BF14 -> 0
B27: FUEL IN TANKS (KG) | O27: FUEL IN TANKS (KG) | AB27: FUEL IN TANKS (KG) | AO27: FUEL IN TANKS (KG)
B30: SIGNATURE : | E30: =BC17 -> CAPT. DAVID WIBAWA SAPULETE | O30: SIGNATURE : | R30: =E30 -> CAPT. DAVID WIBAWA SAPULETE | AB30: SIGNATURE : | AE30: =R30 -> CAPT. DAVID WIBAWA SAPULETE | AO30: SIGNATURE : | AR30: =AE30 -> CAPT. DAVID WIBAWA SAPULETE
D31: ( CAPTAIN ) | Q31: ( CAPTAIN ) | AD31: ( CAPTAIN ) | AQ31: ( CAPTAIN )
B34: EST CGO : | D34: =BC11 -> 500 | G34: KGS | O34: EST CGO : | Q34: =BC12 -> 0 | T34: KGS | AB34: EST CGO : | AD34: =BC13 -> 0 | AG34: KGS | AO34: EST CGO : | AQ34: =BC14 -> 0 | AT34: KGS

Sheet 533CBR
B2: CREW BRIEFING REPORT
B4: FLIGHT NO. | C4: 533 | F4: POD 1 | G4: YPPH | I4: POA 1 | J4: WIII | M4: ALTN | N4: ='533'!BH11 -> WIPP | P4: OFP REF NO. | R4: ='533'!BC19 -> 70851
B6: DATE | C6: =TODAY() -> 46283 | F6: POD 2 | G6: =J4 -> WIII | I6: POA 2 | J6: WIII | M6: ALTN | N6: ='533'!BH12 -> 0 | P6: OFP REF NO. | R6: ='533'!BC20 -> 0
B8: A/C REG | C8: ='533'!BB3 -> PK-AZD | F8: POD 3 | G8: WIII | I8: POA 3 | J8: WIBB | M8: ALTN | N8: ='533'!BH13 -> 0 | P8: OFP REF NO. | R8: ='533'!BC21 -> 0
F10: POD 4 | G10: =J8 -> WIBB | I10: POA 4 | J10: WIII | M10: ALTN | N10: ='533'!BH14 -> 0 | P10: OFP REF NO. | R10: ='533'!BC22 -> 0
C12: Terminal Aerodrome Forecasts
C13: YPPH | D13: =#REF! -> #REF!
C14: WIII | D14: =#REF! -> #REF!
C15: WIPP | D15: =#REF! -> #REF!
C16: WARR | D16: =#REF! -> #REF!
C17: WADD | D17: =#REF! -> #REF!
D19: STATION | E19: TIME | F19: Forecasts | K19: STATION | L19: STATION | M19: TIME | N19: Forecasts
D20: IDENTIFIER | K20: IDENTIFIER | L20: IDENTIFIER
C21: POD 1 | D21: =G4 -> YPPH | E21: ='533'!BE4 -> 0.40972222 | F21: 2006/2112 18010KT 9999 FU VV040 | K21: POD 3 | L21: =G8 -> WIII | M21: ='533'!BE6 -> 0.4375
C22: POA 1 | D22: =J4 -> WIII | E22: ='533'!BF4 -> 0.60763889 | F22: BECMG 2013/2015 21005K T | K22: POA 3 | L22: =J8 -> WIBB | M22: ='533'!BF6 -> 0.51041667
D24: STATION | E24: SIGNIFICANT NOTAM's
D25: IDENTIFIER
D27: WIII | E27: =#REF! -> #REF!
D28: YPPH | E28: =#REF! -> #REF!
D29: WADD | E29: =#REF! -> #REF!
D30: WIPP | E30: =#REF! -> #REF!
C31: REMARK / ADDITIONAL NOTE : HEREBY CONFIRM THAT WE HAVE PERFORM FACE TO FACE BRIEFING
E33: DXR ON DUTY | P33: PIC
E34: NAME / SIGN | P34: NAME / SIGN
D38: DANDUNGTRIE H/2677 | N38: ='533'!BC17 -> CAPT. DAVID WIBAWA SAPULETE
D39: -------------------- | P39: -----------------------

Sheet 260
A2: =BB3 -> PKAZK | BB2: =TODAY() -> 46283 | BH2: COMPUTED TIME
A3: ` | N3: ` | AA3: ` | AN3: ` | BB3: PKAZK | BH3: =BE4-BJ3 -> 0.13194444 | BJ3: 0.25
B4: FUEL CHIT | J4: 1 | O4: FUEL CHIT | W4: 2 | AB4: FUEL CHIT | AJ4: 3 | AO4: FUEL CHIT | AW4: 4 | BB4: AWQ 260 | BC4: CGK | BD4: SIN | BE4: 0.38194444 | BF4: 0.45833333
BB5: AWQ 261 | BC5: =BD4 -> SIN | BD5: CGK | BE5: 0.48611111 | BF5: 0.5625
B6: FLIGHT NO | E6: =BB4 -> AWQ 260 | G6: BAY | O6: FLIGHT NO | R6: =BB5 -> AWQ 261 | T6: BAY | AB6: FLIGHT NO | AE6: =BB6 -> AWQ 240 | AG6: BAY | AO6: FLIGHT NO | AR6: =BB7 -> AWQ 241 | AT6: BAY | BB6: AWQ 240 | BC6: CGK | BD6: JHB | BE6: 0.54166667 | BF6: 0.60763889
B7: ACFT REG | E7: =BB3 -> PKAZK | G7: ETD | H7: =BE4 -> 0.38194444 | O7: ACFT REG | R7: =E7 -> PKAZK | T7: ETD | U7: =BE5 -> 0.48611111 | AB7: ACFT REG | AE7: =R7 -> PKAZK | AG7: ETD | AH7: =BE6 -> 0.54166667 | AO7: ACFT REG | AR7: =AE7 -> PKAZK | AT7: ETD | AU7: =BE7 -> 0.625 | BB7: AWQ 241 | BC7: =BD6 -> JHB | BD7: CGK | BE7: 0.625 | BF7: 0.69791667
B8: ORIGIN | E8: =BC4 -> CGK | G8: TRIP | H8: =BD11 -> 0 | O8: ORIGIN | R8: =BC5 -> SIN | T8: TRIP | U8: =BD12 -> 0 | AB8: ORIGIN | AE8: =BC6 -> CGK | AG8: TRIP | AH8: =BD13 -> 0 | AO8: ORIGIN | AR8: =BC7 -> JHB | AT8: TRIP | AU8: =BD14 -> 0
B9: DATE | E9: =BB2 -> 46283 | G9: NO.PAX | H9: =BB11 -> 0 | O9: DATE | R9: =E9 -> 46283 | T9: NO.PAX | U9: =BB12 -> 0 | AB9: DATE | AE9: =R9 -> 46283 | AG9: NO.PAX | AH9: =BB13 -> 0 | AO9: DATE | AR9: =AE9 -> 46283 | AT9: NO.PAX | AU9: =BB14 -> 0
BB10: PAX | BC10: CGO | BD10: navt | BE10: creat | BF10: TAXI | BG10: EZFW | BH10: ATLN | BI10: TANKER | BJ10: SAVING
B11: REGULATED LDG WT | G11: 66000 | O11: REGULATED LDG WT | T11: 66000 | AB11: REGULATED LDG WT | AG11: 66000 | AO11: REGULATED LDG WT | AT11: 66000 | BC11: 0 | BD11: 0 | BE11: 1000 | BF11: =96+120 -> 216 | BH11: WMKJ | BI11: 0 | BJ11: 0
B12: ADD BURN OFF | G12: =H8 -> 0 | O12: ADD BURN OFF | T12: =U8 -> 0 | AB12: ADD BURN OFF | AG12: =AH8 -> 0 | AO12: ADD BURN OFF | AT12: =BD14 -> 0 | BC12: 0 | BD12: 0 | BE12: 1000 | BF12: =84+108 -> 192 | BH12: WIPP | BI12: 3000 | BJ12: 585.32
B13: REGULATED TKOF WT | F13: A | G13: =G11+G12 -> 66000 | O13: REGULATED TKOF WT | S13: A | T13: =T11+T12 -> 66000 | AB13: REGULATED TKOF WT | AF13: A | AG13: =AG11+AG12 -> 66000 | AO13: REGULATED TKOF WT | AS13: A | AT13: =AT11+AT12 -> 66000
BH14: 4
B15: FORECAST WIND | I15: FLAP | O15: FORECAST WIND | V15: FLAP | AB15: FORECAST WIND | AI15: FLAP | AO15: FORECAST WIND | AV15: FLAP
B16: TEMP | E16: RWY | I16: QNH | O16: TEMP | R16: RWY | V16: QNH | AB16: TEMP | AE16: RWY | AI16: QNH | AO16: TEMP | AR16: RWY | AV16: QNH
B17: REGULATED TKOF WT | F17: B | G17: 73500 | O17: REGULATED TKOF WT | S17: B | T17: =G17 -> 73500 | AB17: REGULATED TKOF WT | AF17: B | AG17: =T17 -> 73500 | AO17: REGULATED TKOF WT | AS17: B | AT17: =AG17 -> 73500 | BB17: PIC NAME : | BC17: CAPT. AUDI PRADHIPTO BRASALI
B19: LOWER RTOW A OR B | G19: =G13 -> 66000 | O19: LOWER RTOW A OR B | T19: =T13 -> 66000 | AB19: LOWER RTOW A OR B | AG19: =AG13 -> 66000 | AO19: LOWER RTOW A OR B | AT19: =AT13 -> 66000 | BB19: OFP1 | BC19: 71119
B20: ESTIMATED ZFW | G20: =BG11 -> 0 | O20: ESTIMATED ZFW | T20: =BG12 -> 0 | AB20: ESTIMATED ZFW | AG20: =BG13 -> 0 | AO20: ESTIMATED ZFW | AT20: =BG14 -> 0 | BB20: OFP2 | BC20: 71120
B21: MAX FUEL AVAILABLE | G21: =G19-G20 -> 66000 | O21: MAX FUEL AVAILABLE | T21: =T19-T20 -> 66000 | AB21: MAX FUEL AVAILABLE | AG21: =AG19-AG20 -> 66000 | AO21: MAX FUEL AVAILABLE | AT21: =AT19-AT20 -> 66000 | BB21: OFP3
B22: MIN SECTOR FUEL | G22: =BE11 -> 1000 | O22: MIN SECTOR FUEL | T22: =BE12 -> 1000 | AB22: MIN SECTOR FUEL | AG22: =BE13 -> 0 | AO22: MIN SECTOR FUEL | AT22: =BE14 -> 0 | BB22: OFP4
B23: EXCESS FUEL AVAILABLE | G23: =G21-G22 -> 65000 | O23: EXCESS FUEL AVAILABLE | T23: =T21-T22 -> 65000 | AB23: EXCESS FUEL AVAILABLE | AG23: =AG21-AG22 -> 66000 | AO23: EXCESS FUEL AVAILABLE | AT23: =AT21-AT22 -> 66000
BB24: MEL | BC24: MEL
B25: LOADSHEET | O25: LOADSHEET | AB25: LOADSHEET | AO25: LOADSHEET
B26: PLUS TAXI FUEL | G26: =BF11 -> 216 | O26: PLUS TAXI FUEL | T26: =BF12 -> 192 | AB26: PLUS TAXI FUEL | AG26: =BF13 -> 0 | AO26: PLUS TAXI FUEL | AT26: =BF14 -> 0
B27: FUEL IN TANKS (KG) | O27: FUEL IN TANKS (KG) | AB27: FUEL IN TANKS (KG) | AO27: FUEL IN TANKS (KG)
B30: SIGNATURE : | E30: =BC17 -> CAPT. AUDI PRADHIPTO BRASALI | O30: SIGNATURE : | R30: =E30 -> CAPT. AUDI PRADHIPTO BRASALI | AB30: SIGNATURE : | AE30: =R30 -> CAPT. AUDI PRADHIPTO BRASALI | AO30: SIGNATURE : | AR30: =AE30 -> CAPT. AUDI PRADHIPTO BRASALI
D31: ( CAPTAIN ) | Q31: ( CAPTAIN ) | AD31: ( CAPTAIN ) | AQ31: ( CAPTAIN )
B34: EST CGO : | D34: =BC11 -> 0 | G34: KGS | O34: EST CGO : | Q34: =BC12 -> 0 | T34: KGS | AB34: EST CGO : | AD34: =BC13 -> 0 | AG34: KGS | AO34: EST CGO : | AQ34: =BC14 -> 0 | AT34: KGS

Sheet 260CBR
B2: CREW BRIEFING REPORT
B4: FLIGHT NO. | C4: 260/261 | F4: POD 1 | G4: WIII | I4: POA 1 | J4: WSSS | M4: ALTN | N4: ='260'!BH11 -> WMKJ | P4: OFP REF NO. | R4: ='260'!BC19 -> 71119
B6: DATE | C6: =TODAY() -> 46283 | F6: POD 2 | G6: =J4 -> WSSS | I6: POA 2 | J6: WIII | M6: ALTN | N6: ='260'!BH12 -> WIPP | P6: OFP REF NO. | R6: ='260'!BC20 -> 71120
B8: A/C REG | C8: ='260'!BB3 -> PKAZK | F8: POD 3 | G8: =J6 -> WIII | I8: POA 3 | J8: WMKJ | M8: ALTN | N8: ='260'!BH13 -> 0 | P8: OFP REF NO. | R8: ='260'!BC21 -> 0
F10: POD 4 | G10: =J8 -> WMKJ | I10: POA 4 | J10: WIII | M10: ALTN | N10: ='260'!BH14 -> 4 | P10: OFP REF NO. | R10: ='260'!BC22 -> 0
C12: Terminal Aerodrome Forecasts
C13: WIII | D13: =#REF! -> #REF!
C14: WSSS | D14: =#REF! -> #REF!
C15: WMKJ | D15: =#REF! -> #REF!
C16: WMKK | D16: =#REF! -> #REF!
C17: WIPP | D17: =#REF! -> #REF!
D19: STATION | E19: TIME | F19: Forecasts | K19: STATION | L19: STATION | M19: TIME | N19: Forecasts
D20: IDENTIFIER | K20: IDENTIFIER | L20: IDENTIFIER
C21: POD 1 | D21: =G4 -> WIII | E21: ='260'!BE4 -> 0.38194444 | F21: 2106/2212 35010KT 7000 SCT020 | K21: POD 3 | L21: =G8 -> WIII | M21: ='260'!BE6 -> 0.54166667
C22: POA 1 | D22: =J4 -> WSSS | E22: ='260'!BF4 -> 0.45833333 | F22: 2106/2212 17008KT 9999 FEW015 SCT020 | K22: POA 3 | L22: =J8 -> WMKJ | M22: ='260'!BF6 -> 0.60763889
C23: POD 2 | D23: =G6 -> WSSS | E23: ='260'!BE5 -> 0.48611111 | F23: 2106/2212 17008KT 9999 FEW015 SCT020 | K23: POD 4 | L23: =G10 -> WMKJ | M23: ='260'!BE7 -> 0.625
C24: POA 2 | D24: =J6 -> WIII | E24: ='260'!BF5 -> 0.5625 | F24: BECMG 2113/2115 21005K T | K24: POA 4 | L24: =J10 -> WIII | M24: ='260'!BF7 -> 0.69791667
D26: STATION | E26: SIGNIFICANT NOTAM's
D27: IDENTIFIER
D29: WIII | E29: =#REF! -> #REF!
D30: WSSS | E30: =#REF! -> #REF!
D31: WMKJ | E31: =#REF! -> #REF!
D32: WMKK | E32: =#REF! -> #REF!
D33: WIPP | E33: =#REF! -> #REF!
C34: REMARK / ADDITIONAL NOTE : HEREBY CONFIRM THAT WE HAVE PERFORM FACE TO FACE BRIEFING
H36: DXR ON DUTY | P36: PIC
H37: NAME / SIGN | P37: NAME / SIGN
G41: DANDUNG TRIE H / 2677 | O41: ='260'!BC17 -> CAPT. AUDI PRADHIPTO BRASALI
H42: -------------------- | P42: -----------------------

Sheet AFTN N EMAIL
A1: AFTN : | B1: nmc_ofp@airasia.com,atc.messages@flightfocus.net
A2: EMAIL : | B2: WMFPYFYX,iaa_cgk_ops@airasia.com
B3: opsper@skystar.com.au, loco_per@skystar.com.au, iaa_per_ops@airasia.com, stevemcqueen@airasia.com,iaa_dps_ops@airasia.com
B4: yuloktavinojulidar@airasia.com,mochamadruslani@airasia.com,nandangprianto@airasia.com,yudhonobudilaksono@airasia.com,ignatiussuryadi@airasia.com,rendisantana@airasia.com,allobudiyanto@airasia.com
B6: ATC FLIGHT PLAN DMK-CGK
B7: (FPL-AWQ253-IS | O7: AFTN CGK | Q7: WIIIYOYW
B8: -A320/M-SDFGHIWRY/LB1
B9: -VTBD1355 | O9: PASSWORD AIM ATC FLIGHT PLAN :
B10: -N0457F350 GRANT3A N891 RYN M644 VKB M751 VPK B469 VMR B338 | O10: IAAOCC
B11: VTK/M077F350 B338 ANITO/N0455F350 B470 BUNIK BUNIK1A | O11: 123AWQ
B12: -WIII0316 WSSS | O12: 1014
B13: -PBN/A1B1C1D1O1 DOF/140918 REG/PKAXV
B14: EET/WMFC0111 WSJC0154 WIIF0207 | K14: ETP AUS : | L14: IN | M14: YPPH YPLM | O14: dcapenang@dca.gov.my | V14: www.meteosoekarnohatta.com
B15: SEL/CRBJ PER/C RMK/TCAS EQUIPPED | L15: OUT | M15: YPLM WADD | V15: User Name : iaa_cgk
B16: E/0528 P/TBN R/VE A/RED AND WHITE C/TBN) | V16: Password : airasia123
K18: LINK AIMS : | Q18: 5506110 | R18: ARRO
B19: ROUTE BDO-DPS | K19: http://aamy-xensf01/Citrix/AIMSWeb/ | Q19: 5506111 | R19: BO N NOTAM
Q20: 5506126 | R20: ATFM
B21: WICC RWY-29 CA1 CA W45 SBR W33 RABOL RABOL3F RWY-27 WADD | K21: AIM JAKARTA AIS | Q21: 5505497 | R21: ATFM
K22: http://www.aim-jakarta.co.id/ | Q22: 5505163 | R22: AOC APPROVAL FOR FERRY
K24: DARWIN VAAC :
A25: crewing 021 28040778 | K25: http://www.bom.gov.au/info/vaac/advisories.shtml
A26: 021 29850924 eng 0361 8877135 / 081936255599 | R26: https://efpl.airnavindonesia.co.id/?link=login
A27: occ cgk 021 29850923 it admin 02128040786 | K27: SLOTTER
A28: BO DPS 0877 6028 0178 erry 08119990199 | K28: http://chronos.atfm.co.id/ | N28: LOGIN : awq_cgk
A29: 75103 BANDUNG OCC 0226046190 | N29: PASS : 123
A30: occ dps 0361 9360277 sub occ 031 8688535
A31: 0361 8491809 | B31: BO DPS 0361-9361357 | I31: ADDS WX
I32: https://www.aviationweather.gov/adds/tafs?station_ids=wiii+wihh+wipp+wimm+warr+wadd+wadl+waaa+wsss+wmkk+wmkp+wmkj+wmsa+vtbs+vtbd+vtbu+vtcc&std_trans=standard&submit_both=Get+TAFs+and+METARs
A33: WADDYOYE, BAGUSHERMAWAN@AIRASIA.COM, IAA_DPS_OPS@AIRASIA.COM
A35: NMC_OFP@AIRASIA.COM, ATC.MESSAGES@FLIGHTFOCUS.NET, ferdiansyah@airasia.com
A37: saa_groundops@airasia.com, saa_gscontroller@airasia.com, ferdiansyah@airasia.com
A38: maa_kul_gscontroller@airasia.com, maa_kul_groundops@airasia.com, iaa_dps_ops@airasia.com
A39: maa_bki_gscontroller@airasia.com, maa_bki_groundops@airasia.com, iaa_dps_ops@airasia.com , ferdiansyah@airasia.com
A40: opsper@skystar.com.au , loco_per@skystar.com.au, iaa_per_ops@airasia.com, stevemcqueen@airasia.com, iaa_dps_ops@airasia.com, ferdiansyah@airasia.com
A42: YBBBZRZX, drw.ops@menziesaviation.com, iaa_drw_ops@airasia.com, stevemcqueen@airasia.com, iaa_dps_ops@airasia.com, ferdiansyah@airasia.com
A43: http://www.radarbox24.com/
A45: aax_ops_per@airasia.com,
A47: atc.messages@flightfocus.net,
A49: iaa_dps_ramp@airasia.com.
...

Sheet ALT MOR
A1: FAIR WEATHER ALTERNATE
A4: NO | B4: DATE | D4: FLIGHT NO | E4: DEP | F4: ARR | G4: ALT | H4: *If unable to close-in alternate, please state the reason.
B5: =TODAY() -> 46283
A6: 2 | C6: QZ | D6: 7510 | E6: CGK | F6: DPS | G6: LOP
C7: QZ | D7: 7511 | E7: DPS | F7: CGK | G7: HLP
C8: QZ | D8: 7552 | E8: CGK | F8: JOG | G8: SUB
C9: QZ | D9: 7553 | E9: JOG | F9: CGK | G9: HLP
A11: 1 | C11: QZ | D11: 200 | E11: CGK | F11: KUL | G11: SZB
C12: QZ | D12: 129 | E12: KUL | F12: KNO | G12: PEN
C13: QZ | D13: 108 | E13: KNO | F13: PEN | G13: KNO
C14: QZ | D14: 109 | E14: PEN | F14: KNO | G14: PEN
A16: 4 | C16: QZ | D16: 7688 | E16: CGK | F16: SUB | G16: DPS
C17: QZ | D17: 7689 | E17: SUB | F17: CGK | G17: PLM
C18: QZ | D18: 7520 | E18: CGK | F18: DPS | G18: LOP
C19: QZ | D19: 7521 | E19: DPS | F19: CGK | G19: PLM
A21: 3 | C21: QZ | D21: 7556 | E21: CGK | F21: JOG | G21: SUB
C22: QZ | D22: 658 | E22: JOG | F22: SIN | G22: JHB
C23: QZ | D23: 659 | E23: SIN | F23: JOG | G23: SUB
C24: QZ | D24: 7557 | E24: JOG | F24: CGK | G24: HLP
A26: 5 | C26: QZ | D26: 202 | E26: CGK | F26: KUL | G26: SZB
C27: QZ | D27: 280 | E27: KUL | F27: PNK | G27: KCH
C28: QZ | D28: 281 | E28: PNK | F28: KUL | G28: JHB
C29: QZ | D29: 203 | E29: KUL | F29: CGK | G29: HLP
C31: QZ | D31: 7516 | E31: CGK | F31: DPS | G31: LOP
C32: QZ | D32: 7517 | E32: DPS | F32: CGK | G32: PLM
A34: 6 | C34: QZ | D34: 700 | E34: CGK | F34: SRG | G34: SUB
C35: QZ | D35: 701 | E35: SRG | F35: CGK | G35: HLP
C36: QZ | D36: 614 | E36: CGK | F36: LOP | G36: DPS
C37: QZ | D37: 615 | E37: LOP | F37: CGK | G37: HLP
A39: 7 | C39: QZ | D39: 262 | E39: CGK | F39: SIN | G39: JHB
C40: QZ | D40: 263 | E40: SIN | F40: CGK | G40: HLP
A41: 11 | D41: =[1]INPUT!B44 -> #REF! | E41: =[1]INPUT!C44 -> #REF! | F41: =[1]INPUT!D44 -> #REF!
A42: 12 | D42: =[1]INPUT!B45 -> #REF! | E42: =[1]INPUT!C45 -> #REF! | F42: =[1]INPUT!D45 -> #REF!
A43: 13 | D43: =[1]INPUT!B46 -> #REF! | E43: =[1]INPUT!C46 -> #REF! | F43: =[1]INPUT!D46 -> #REF!
A44: 14 | D44: =[1]INPUT!B47 -> #REF! | E44: =[1]INPUT!C47 -> #REF! | F44: =[1]INPUT!D47 -> #REF!
D45: =[1]INPUT!B48 -> #REF! | E45: =[1]INPUT!C48 -> #REF! | F45: =[1]INPUT!D48 -> #REF!
D46: =[1]INPUT!B44 -> #REF! | E46: =[1]INPUT!C44 -> #REF! | F46: =[1]INPUT!D44 -> #REF!
A47: 8 | C47: QZ | D47: 250 | E47: CGK | F47: DMK | G47: BKK
C48: QZ | D48: 251 | E48: DMK | F48: CGK | G48: HLP
D49: 7526 | E49: CGK | F49: DPS
...

Sheet 258
A2: =BB3 -> PK-AZD | BB2: =TODAY() -> 46283 | BH2: COMPUTED TIME
A3: ` | N3: ` | AA3: ` | AN3: ` | BB3: PK-AZD | BH3: =BE4-BJ3 -> 0.24305556 | BJ3: 0.25
B4: FUEL CHIT | J4: 1 | O4: FUEL CHIT | W4: 2 | AB4: FUEL CHIT | AJ4: 3 | AO4: FUEL CHIT | AW4: 4 | BB4: AWQ 258 | BC4: CGK | BD4: DMK | BE4: 0.49305556 | BF4: 0.64583333
BB5: AWQ 259 | BC5: =BD4 -> DMK | BD5: CGK | BE5: 0.66666667 | BF5: 0.8125 | BG5: =BB3 -> PK-AZD
B6: FLIGHT NO | E6: =BB4 -> AWQ 258 | G6: BAY | O6: FLIGHT NO | R6: =BB5 -> AWQ 259 | T6: BAY | AB6: FLIGHT NO | AE6: =BB6 -> AWQ 202 | AG6: BAY | AO6: FLIGHT NO | AR6: =BB7 -> AWQ 203 | AT6: BAY | BB6: AWQ 202 | BC6: CGK | BD6: KUL | BE6: 0.47916667 | BF6: 0.56597222 | BH6: COMPUTED TIME
B7: ACFT REG | E7: =BB3 -> PK-AZD | G7: ETD | H7: =BE4 -> 0.49305556 | O7: ACFT REG | R7: =BG5 -> PK-AZD | T7: ETD | U7: =BE5 -> 0.66666667 | AB7: ACFT REG | AE7: =R7 -> PK-AZD | AG7: ETD | AH7: =BE6 -> 0.47916667 | AO7: ACFT REG | AR7: =AE7 -> PK-AZD | AT7: ETD | AU7: =BE7 -> 0.58333333 | BB7: AWQ 203 | BC7: =BD6 -> KUL | BD7: CGK | BE7: 0.58333333 | BF7: 0.67013889 | BH7: =BE4-BJ7 -> 0.36805556 | BJ7: 0.125
B8: ORIGIN | E8: =BC4 -> CGK | G8: TRIP | H8: =BD11 -> 0 | O8: ORIGIN | R8: =BC5 -> DMK | T8: TRIP | U8: =BD12 -> 0 | AB8: ORIGIN | AE8: =BC6 -> CGK | AG8: TRIP | AH8: =BD13 -> 0 | AO8: ORIGIN | AR8: =BC7 -> KUL | AT8: TRIP | AU8: =BD14 -> 0
B9: DATE | E9: =BB2-1 -> 46282 | G9: NO.PAX | H9: =BB11 -> 0 | O9: DATE | R9: =E9+1 -> 46283 | T9: NO.PAX | U9: =BB12 -> 0 | AB9: DATE | AE9: =R9 -> 46283 | AG9: NO.PAX | AH9: =BB13 -> 0 | AO9: DATE | AR9: =AE9 -> 46283 | AT9: NO.PAX | AU9: =BB14 -> 0
BB10: WAG | BC10: CGO | BD10: NAVT | BE10: CREAT | BF10: TAXI | BG10: EZFW | BH10: ALTN | BI10: TANKER | BJ10: SAVING
B11: REGULATED LDG WT | G11: 66000 | O11: REGULATED LDG WT | T11: 66000 | AB11: REGULATED LDG WT | AG11: 66000 | AO11: REGULATED LDG WT | AT11: 66000 | BC11: 0 | BD11: 0 | BE11: 1000 | BF11: =120+72 -> 192 | BH11: VTBU | BI11: 0 | BJ11: 0
B12: ADD BURN OFF | G12: =H8 -> 0 | O12: ADD BURN OFF | T12: =U8 -> 0 | AB12: ADD BURN OFF | AG12: =AH8 -> 0 | AO12: ADD BURN OFF | AT12: =AU8 -> 0 | BC12: 0 | BD12: 0 | BE12: 500 | BF12: =96+72 -> 168 | BH12: WSSS | BI12: 1000 | BJ12: 162.5
B13: REGULATED TKOF WT | F13: A | G13: =G11+G12 -> 66000 | O13: REGULATED TKOF WT | S13: A | T13: =T11+T12 -> 66000 | AB13: REGULATED TKOF WT | AF13: A | AG13: =AG11+AG12 -> 66000 | AO13: REGULATED TKOF WT | AS13: A | AT13: =AT11+AT12 -> 66000
B15: FORECAST WIND | I15: FLAP | O15: FORECAST WIND | V15: FLAP | AB15: FORECAST WIND | AI15: FLAP | AO15: FORECAST WIND | AV15: FLAP
B16: TEMP | E16: RWY | I16: QNH | O16: TEMP | R16: RWY | V16: QNH | AB16: TEMP | AE16: RWY | AI16: QNH | AO16: TEMP | AR16: RWY | AV16: QNH
B17: REGULATED TKOF WT | F17: B | G17: 73500 | O17: REGULATED TKOF WT | S17: B | T17: =G17 -> 73500 | AB17: REGULATED TKOF WT | AF17: B | AG17: 73500 | AO17: REGULATED TKOF WT | AS17: B | AT17: 73500 | BB17: PIC NAME | BC17: CAPT. REZA PAHLEVI
B19: LOWER RTOW A OR B | G19: =G13 -> 66000 | O19: LOWER RTOW A OR B | T19: =T13 -> 66000 | AB19: LOWER RTOW A OR B | AG19: =AG13 -> 66000 | AO19: LOWER RTOW A OR B | AT19: =AT13 -> 66000 | BB19: OFP1 | BC19: 71137
B20: ESTIMATED ZFW | G20: =BG11 -> 0 | O20: ESTIMATED ZFW | T20: =BG12 -> 0 | AB20: ESTIMATED ZFW | AG20: =BG13 -> 0 | AO20: ESTIMATED ZFW | AT20: =BG14 -> 0 | BB20: OFP2 | BC20: 71141
B21: MAX FUEL AVAILABLE | G21: =G19-G20 -> 66000 | O21: MAX FUEL AVAILABLE | T21: =T19-T20 -> 66000 | AB21: MAX FUEL AVAILABLE | AG21: =AG19-AG20 -> 66000 | AO21: MAX FUEL AVAILABLE | AT21: =AT19-AT20 -> 66000 | BB21: OFP3
B22: MIN SECTOR FUEL | G22: =BE11 -> 1000 | O22: MIN SECTOR FUEL | T22: =BE12 -> 500 | AB22: MIN SECTOR FUEL | AG22: =BE13 -> 0 | AO22: MIN SECTOR FUEL | AT22: =BE14 -> 0 | BB22: OFP4
B23: EXCESS FUEL AVAILABLE | G23: =G21-G22 -> 65000 | O23: EXCESS FUEL AVAILABLE | T23: =T21-T22 -> 65500 | AB23: EXCESS FUEL AVAILABLE | AG23: =AG21-AG22 -> 66000 | AO23: EXCESS FUEL AVAILABLE | AT23: =AT21-AT22 -> 66000
B25: LOADSHEET | O25: LOADSHEET | AB25: LOADSHEET | AO25: LOADSHEET | BB25: MEL | BC25: NIL
B26: PLUS TAXI FUEL | G26: =BF11 -> 192 | O26: PLUS TAXI FUEL | T26: =BF12 -> 168 | AB26: PLUS TAXI FUEL | AG26: =BF13 -> 0 | AO26: PLUS TAXI FUEL | AT26: =BF14 -> 0
B27: FUEL IN TANKS (KG) | O27: FUEL IN TANKS (KG) | AB27: FUEL IN TANKS (KG) | AO27: FUEL IN TANKS (KG)
B30: SIGNATURE : | E30: =BC17 -> CAPT. REZA PAHLEVI | O30: SIGNATURE : | R30: =E30 -> CAPT. REZA PAHLEVI | AB30: SIGNATURE : | AE30: =R30 -> CAPT. REZA PAHLEVI | AO30: SIGNATURE : | AR30: =AE30 -> CAPT. REZA PAHLEVI
D31: ( CAPTAIN ) | Q31: ( CAPTAIN ) | AD31: ( CAPTAIN ) | AQ31: ( CAPTAIN )
B34: EST CGO : | D34: =BC11 -> 0 | G34: KGS | O34: EST CGO : | Q34: =BC12 -> 0 | T34: KGS | AB34: EST CGO : | AD34: =BC13 -> 0 | AG34: KGS | AO34: EST CGO : | AQ34: =BC14 -> 0 | AT34: KGS

Sheet 258CBR
B2: CREW BRIEFING REPORT
B4: FLIGHT NO. | C4: 258/259 | F4: POD 1 | G4: WIII | I4: POA 1 | J4: VTBD | M4: ALTN | N4: ='258'!BH11 -> VTBU | P4: OFP REF NO. | R4: ='258'!BC19 -> 71137
B6: DATE | C6: ='258'!BB2 -> 46283 | F6: POD 2 | G6: =J4 -> VTBD | I6: POA 2 | J6: WIII | M6: ALTN | N6: ='258'!BH12 -> WSSS | P6: OFP REF NO. | R6: ='258'!BC20 -> 71141
B8: A/C REG | C8: ='258'!BB3 -> PK-AZD | F8: POD 3 | G8: WIII | I8: POA 3 | J8: WMKK | M8: ALTN | P8: OFP REF NO. | R8: #REF!
F10: POD 4 | G10: =J8 -> WMKK | I10: POA 4 | J10: WIII | M10: ALTN | P10: OFP REF NO. | R10: #REF!
C12: Terminal Aerodrome Forecasts
C13: WIII | D13: =#REF! -> #REF!
C14: VTBD | D14: =#REF! -> #REF!
C15: VTBS | D15: =#REF! -> #REF!
C16: VTBU | D16: =#REF! -> #REF!
C17: WSSS | D17: =#REF! -> #REF!
D20: STATION | E20: TIME | F20: Forecasts | K20: STATION | L20: STATION | M20: TIME | N20: Forecasts
D21: IDENTIFIER | K21: IDENTIFIER | L21: IDENTIFIER
C22: POD 1 | D22: =G4 -> WIII | E22: ='258'!BE4 -> 0.49305556 | F22: 2106/2212 35010KT 7000 SCT020 | K22: POD 3 | L22: =G8 -> WIII | M22: ='258'!BE6 -> 0.47916667
C23: POA 1 | D23: =J4 -> VTBD | E23: ='258'!BF4 -> 0.64583333 | F23: TEMPO 2114/2118 VRB15KT 3000 TSRA FEW018CB SCT030 BKN100 | K23: POA 3 | L23: =J8 -> WMKK | M23: ='258'!BF6 -> 0.56597222
C24: POD 2 | D24: =G6 -> VTBD | E24: ='258'!BE5 -> 0.66666667 | F24: TEMPO 2114/2118 VRB15KT 3000 TSRA FEW018CB SCT030 BKN100 | K24: POD 4 | L24: =G10 -> WMKK | M24: ='258'!BE7 -> 0.58333333
C25: POA 2 | D25: =J6 -> WIII | E25: ='258'!BF5 -> 0.8125 | F25: 2106/2212 35010KT 7000 SCT020 | K25: POA 4 | L25: =J10 -> WIII | M25: ='258'!BF7 -> 0.67013889
D27: STATION | E27: SIGNIFICANT NOTAM's
D28: IDENTIFIER
D30: WIII | E30: =#REF! -> #REF!
D31: VTBD | E31: =#REF! -> #REF!
D32: VTBS | E32: =#REF! -> #REF!
D33: VTBU | E33: =#REF! -> #REF!
D34: WSSS | E34: =#REF! -> #REF!
C35: REMARK / ADDITIONAL NOTE : HEREBY CONFIRM THAT WE HAVE PERFORM FACE TO FACE BRIEFING
H37: DXR ON DUTY | P37: PIC
H38: NAME / SIGN | P38: NAME / SIGN
G41: DANDUNG TRIE H / 2677 | O41: ='258'!BC17 -> CAPT. REZA PAHLEVI
G42: -------------------- | P42: -----------------------

Sheet TANKERING
A1: TANKERING CGK HUB
A4: NO | B4: DATE | C4: FLIGHT - QZ | D4: DEP | E4: ARR | F4: AMOUNT (KG) | G4: SAVING (US$)
A5: 1 | B5: =TODAY() -> 46283 | C5: #REF! | F5: #REF! | G5: #REF!
A6: 2 | C6: #REF! | F6: #REF! | G6: #REF!
A7: 3 | C7: ='860'!BB4 -> AWQ 860 | F7: ='860'!BI11 -> 2000 | G7: ='860'!BJ11 -> 95.2
A8: 4 | C8: #REF! | F8: #REF! | G8: #REF!
A9: 5 | C9: #REF! | F9: #REF! | G9: #REF!
A10: 6 | C10: #REF! | F10: #REF! | G10: #REF!
A11: 7 | C11: #REF! | F11: #REF! | G11: #REF!
A12: 8 | C12: #REF! | F12: #REF! | G12: #REF!
A13: 9 | C13: #REF! | F13: #REF! | G13: #REF!
A14: 10 | C14: #REF! | F14: #REF! | G14: #REF!
A15: 11 | C15: ='258'!BB4 -> AWQ 258 | F15: ='258'!BI11 -> 0 | G15: ='258'!BJ11 -> 0
A16: 12 | C16: #REF! | F16: #REF! | G16: #REF!
A17: 13 | C17: #REF! | F17: #REF! | G17: #REF!
A18: 14 | C18: AWQ 527 | F18: ='526'!BI12 -> 3000 | G18: ='526'!BJ12 -> 329.75
A19: 15
A20: 16
A21: 17
A22: 18
A23: 19
A24: 20
A25: 21
A26: 22
A27: 24
A28: 25
A29: 26
A30: 27
... A44: 41
E45: TOTAL | F45: =SUM(F5:F44) -> 5000 | G45: =SUM(G5:G44) -> 424.95

Sheet CARGO
B3: CARGO ANALISA PER-HARI INI
A5: FLIGHT | B5: WAG | C5: TELEPORT | D5: NAVTEC | E5: CREAT | I5: QZ200 | J5: CGK | K5: KUL | L5: KNO
I6: QZ201 | J6: KUL | K6: CGK | L6: TKG
I7: QZ802 | J7: CGK | K7: DPS | L7: LOP
I8: QZ803 | J8: DPS | K8: CGK | L8: TKG
I9: QZ202 | J9: CGK | K9: KUL | L9: KNO
I10: QZ203 | J10: KUL | K10: CGK | L10: TKG
I11: QZ262 | J11: CGK | K11: SIN | L11: KUL
I12: QZ263 | J12: SIN | K12: CGK | L12: TKG
I13: QZ250 | J13: CGK | K13: DMK | L13: BKK
I14: QZ251 | J14: DMK | K14: CGK | L14: TKG
I15: QZ530 | J15: CGK | K15: KCH | L15: BKI
I16: QZ531 | J16: KCH | K16: CGK | L16: TKG
I17: QZ724 | J17: CGK | K17: DTB | L17: KNO
... I59: QZ811 | J59: DPS | K59: CGK | L59: DPS

Sheet NAMA
A2: NO | B2: NAMA | D2: NO | E2: NAMA
A3: 1 | B3: CAPT. ACHMAD NIBRASKA MUHARROM | E3: CAPT. WILLIAM WIRAWAN
A4: 2 | B4: CAPT. ANDI DWI CAHYADI | E4: CAPT. REZA PAHLEVI
A5: 3 | B5: CAPT. ANDY ANDRIYAN | E5: CAPT. HARRY KARYADHIE ARTHONO
A6: 4 | B6: CAPT. ARDILES SOMPOTAN | E6: CAPT. ADITYA HERGIANTOMO
A7: 5 | B7: CAPT. CHRISTANTO DHONOMIDJOJO | E7: CAPT. BRAM DIRGANTARA PUTRA
A8: 6 | B8: CAPT. EKO SUHERWANTO | E8: CAPT. JULIAN HENDRA
A9: 7 | B9: CAPT. FEBI IRAWAN | E9: CAPT. RIO ARIESTA RATULONA
A10: 8 | B10: CAPT. FELLIAS | E10: CAPT. MOHAMMAD DENYNDRA RAMADHAN
A11: 9 | B11: CAPT. IBRAHIM AJI ISHAQ | E11: CAPT. M. ARIE NOVAN WIBISONO
A12: 10 | B12: CAPT. JATI ASTU PRATAMA PUTRA
A13: 11 | B13: CAPT. PRADIDO HADIWINOTO
A14: 12 | B14: CAPT. RAHADI MUHAMMAD MANTIKNO
A15: 13 | B15: CAPT. SANJAYA GUNAWAN
A16: 14 | B16: CAPT. WICAKSONO
A17: 15 | B17: CAPT. WIDHI WIDAGDO
A18: 16 | B18: CAPT. WIEMAR ADI NUGROHO
